ERROR 2022-09-28 14:17:40,722 assertbase.py _teardown_collect 273 <bound method FirstTest.test_02_add_device_index of <minitest.FirstTest testMethod=test_02_add_device_index>>
Traceback (most recent call last):
  File "/Library/Frameworks/Python.framework/Versions/3.10/lib/python3.10/site-packages/minium/framework/libs/unittest/case.py", line 32, in testPartExecutor
    yield
  File "/Library/Frameworks/Python.framework/Versions/3.10/lib/python3.10/site-packages/minium/framework/libs/unittest/case.py", line 118, in run
    self._callTestMethod(testMethod)
  File "/Library/Frameworks/Python.framework/Versions/3.10/lib/python3.10/unittest/case.py", line 549, in _callTestMethod
    method()
  File "/Users/isentech/Desktop/python/miniu_test/minitest.py", line 36, in test_02_add_device_index
    self.assertEqual(devices_sum,1)
  File "/Library/Frameworks/Python.framework/Versions/3.10/lib/python3.10/site-packages/minium/framework/assertbase.py", line 354, in _hook_assert
    return attr(*args, **kwargs)
  File "/Applications/PyCharm CE.app/Contents/plugins/python-ce/helpers/pycharm/teamcity/diff_tools.py", line 33, in _patched_equals
    old(self, first, second, msg)
  File "/Library/Frameworks/Python.framework/Versions/3.10/lib/python3.10/unittest/case.py", line 845, in assertEqual
    assertion_func(first, second, msg=msg)
  File "/Library/Frameworks/Python.framework/Versions/3.10/lib/python3.10/unittest/case.py", line 838, in _baseAssertEqual
    raise self.failureException(msg)
AssertionError: 0 != 1
