ERROR 2022-09-27 15:20:16,372 assertbase.py _teardown_collect 273 <bound method FirstTest.test_01_bing_device of <minitest.FirstTest testMethod=test_01_bing_device>>
Traceback (most recent call last):
  File "/Library/Frameworks/Python.framework/Versions/3.10/lib/python3.10/site-packages/minium/framework/libs/unittest/case.py", line 32, in testPartExecutor
    yield
  File "/Library/Frameworks/Python.framework/Versions/3.10/lib/python3.10/site-packages/minium/framework/libs/unittest/case.py", line 118, in run
    self._callTestMethod(testMethod)
  File "/Library/Frameworks/Python.framework/Versions/3.10/lib/python3.10/unittest/case.py", line 549, in _callTestMethod
    method()
  File "/Users/isentech/Desktop/python/miniu_test/minitest.py", line 21, in test_01_bing_device
    self.assertEqual(page,"/pagesDevice/addDevice/addDevice")
  File "/Library/Frameworks/Python.framework/Versions/3.10/lib/python3.10/site-packages/minium/framework/assertbase.py", line 354, in _hook_assert
    return attr(*args, **kwargs)
  File "/Applications/PyCharm CE.app/Contents/plugins/python-ce/helpers/pycharm/teamcity/diff_tools.py", line 33, in _patched_equals
    old(self, first, second, msg)
  File "/Library/Frameworks/Python.framework/Versions/3.10/lib/python3.10/unittest/case.py", line 845, in assertEqual
    assertion_func(first, second, msg=msg)
  File "/Library/Frameworks/Python.framework/Versions/3.10/lib/python3.10/site-packages/minium/framework/assertbase.py", line 354, in _hook_assert
    return attr(*args, **kwargs)
  File "/Library/Frameworks/Python.framework/Versions/3.10/lib/python3.10/unittest/case.py", line 1226, in assertMultiLineEqual
    self.fail(self._formatMessage(msg, standardMsg))
  File "/Library/Frameworks/Python.framework/Versions/3.10/lib/python3.10/unittest/case.py", line 675, in fail
    raise self.failureException(msg)
AssertionError: '/pages/login/login' != '/pagesDevice/addDevice/addDevice'
- /pages/login/login
+ /pagesDevice/addDevice/addDevice

ERROR 2022-09-27 15:20:17,557 connection.py _receive_response 206 [776f28e0-3f0d-4046-816c-f832f8faf523]: no such element
ERROR 2022-09-27 15:20:19,205 assertbase.py _teardown_collect 273 <bound method FirstTest.test_02_add_device_index of <minitest.FirstTest testMethod=test_02_add_device_index>>
Traceback (most recent call last):
  File "/Library/Frameworks/Python.framework/Versions/3.10/lib/python3.10/site-packages/minium/framework/libs/unittest/case.py", line 32, in testPartExecutor
    yield
  File "/Library/Frameworks/Python.framework/Versions/3.10/lib/python3.10/site-packages/minium/framework/libs/unittest/case.py", line 118, in run
    self._callTestMethod(testMethod)
  File "/Library/Frameworks/Python.framework/Versions/3.10/lib/python3.10/unittest/case.py", line 549, in _callTestMethod
    method()
  File "/Users/isentech/Desktop/python/miniu_test/minitest.py", line 25, in test_02_add_device_index
    self.page.get_element("/page/view/view[3]/view[1]/view[1]/view/view/view/view/view/view/view[1]/input").input(de.device_mac)
  File "/Library/Frameworks/Python.framework/Versions/3.10/lib/python3.10/site-packages/minium/miniprogram/base_driver/minium_log.py", line 135, in wrapper
    result = func(*args, **kwargs)
  File "/Library/Frameworks/Python.framework/Versions/3.10/lib/python3.10/site-packages/minium/miniprogram/base_driver/page.py", line 200, in get_element
    return self.get_element_by_xpath(
  File "/Library/Frameworks/Python.framework/Versions/3.10/lib/python3.10/site-packages/minium/miniprogram/base_driver/minium_log.py", line 135, in wrapper
    result = func(*args, **kwargs)
  File "/Library/Frameworks/Python.framework/Versions/3.10/lib/python3.10/site-packages/minium/miniprogram/base_driver/page.py", line 387, in get_element_by_xpath
    raise MiniElementNotFoundError("element[%s] not found" % xpath)
minium.framework.exception.MiniElementNotFoundError: element[/page/view/view[3]/view[1]/view[1]/view/view/view/view/view/view/view[1]/input] not found
ERROR 2022-09-27 16:24:43,898 connection.py _receive_response 206 [9473edec-54e9-40b4-a423-21bc036009af]: can not navigateTo a tabbar page
ERROR 2022-09-27 16:24:46,562 assertbase.py _teardown_collect 273 <bound method FirstTest.test_02_add_device_index of <minitest.FirstTest testMethod=test_02_add_device_index>>
Traceback (most recent call last):
  File "/Library/Frameworks/Python.framework/Versions/3.10/lib/python3.10/site-packages/minium/framework/libs/unittest/case.py", line 32, in testPartExecutor
    yield
  File "/Library/Frameworks/Python.framework/Versions/3.10/lib/python3.10/site-packages/minium/framework/libs/unittest/case.py", line 118, in run
    self._callTestMethod(testMethod)
  File "/Library/Frameworks/Python.framework/Versions/3.10/lib/python3.10/unittest/case.py", line 549, in _callTestMethod
    method()
  File "/Users/isentech/Desktop/python/miniu_test/minitest.py", line 29, in test_02_add_device_index
    self.app.navigate_to("/pages/index/index")
  File "/Library/Frameworks/Python.framework/Versions/3.10/lib/python3.10/site-packages/minium/miniprogram/base_driver/minium_log.py", line 135, in wrapper
    result = func(*args, **kwargs)
  File "/Library/Frameworks/Python.framework/Versions/3.10/lib/python3.10/site-packages/minium/miniprogram/base_driver/app.py", line 308, in navigate_to
    page = self._change_route("navigateTo", url, is_wait_url_change)
  File "/Library/Frameworks/Python.framework/Versions/3.10/lib/python3.10/site-packages/minium/miniprogram/base_driver/app.py", line 475, in _change_route
    self.call_wx_method(open_type, [{"url": path}])
  File "/Library/Frameworks/Python.framework/Versions/3.10/lib/python3.10/site-packages/minium/miniprogram/base_driver/minium_log.py", line 135, in wrapper
    result = func(*args, **kwargs)
  File "/Library/Frameworks/Python.framework/Versions/3.10/lib/python3.10/site-packages/minium/miniprogram/base_driver/app.py", line 247, in call_wx_method
    return self._call_wx_method(method=method, args=args, plugin_appid=plugin_appid)
  File "/Library/Frameworks/Python.framework/Versions/3.10/lib/python3.10/site-packages/minium/miniprogram/base_driver/minium_object.py", line 287, in _call_wx_method
    return self.connection.send("App.callWxMethod", params)
  File "/Library/Frameworks/Python.framework/Versions/3.10/lib/python3.10/site-packages/minium/miniprogram/base_driver/connection.py", line 185, in send
    return self._receive_response(cmd)
  File "/Library/Frameworks/Python.framework/Versions/3.10/lib/python3.10/site-packages/minium/miniprogram/base_driver/connection.py", line 207, in _receive_response
    raise MiniAppError(err_msg)
minium.framework.exception.MiniAppError: can not navigateTo a tabbar page
ERROR 2022-09-27 16:36:42,832 connection.py _on_error       266 Connection to remote host was lost.
ERROR 2022-09-27 16:39:10,650 assertbase.py _teardown_collect 273 <bound method FirstTest.test_02_add_device_index of <minitest.FirstTest testMethod=test_02_add_device_index>>
Traceback (most recent call last):
  File "/Library/Frameworks/Python.framework/Versions/3.10/lib/python3.10/site-packages/minium/framework/libs/unittest/case.py", line 32, in testPartExecutor
    yield
  File "/Library/Frameworks/Python.framework/Versions/3.10/lib/python3.10/site-packages/minium/framework/libs/unittest/case.py", line 118, in run
    self._callTestMethod(testMethod)
  File "/Library/Frameworks/Python.framework/Versions/3.10/lib/python3.10/unittest/case.py", line 549, in _callTestMethod
    method()
  File "/Users/isentech/Desktop/python/miniu_test/minitest.py", line 25, in test_02_add_device_index
    self.page.get_element("/page/view/view[3]/view[1]/view[1]/view/view/view/view/view/view/view[1]/input").input(de.device_mac)
  File "/Library/Frameworks/Python.framework/Versions/3.10/lib/python3.10/site-packages/minium/miniprogram/base_driver/minium_log.py", line 135, in wrapper
    result = func(*args, **kwargs)
  File "/Library/Frameworks/Python.framework/Versions/3.10/lib/python3.10/site-packages/minium/miniprogram/base_driver/page.py", line 200, in get_element
    return self.get_element_by_xpath(
  File "/Library/Frameworks/Python.framework/Versions/3.10/lib/python3.10/site-packages/minium/miniprogram/base_driver/minium_log.py", line 135, in wrapper
    result = func(*args, **kwargs)
  File "/Library/Frameworks/Python.framework/Versions/3.10/lib/python3.10/site-packages/minium/miniprogram/base_driver/page.py", line 385, in get_element_by_xpath
    el = search_element()
  File "/Library/Frameworks/Python.framework/Versions/3.10/lib/python3.10/site-packages/minium/utils/utils.py", line 35, in wrapper
    r = func(*args, **kwargs)
  File "/Library/Frameworks/Python.framework/Versions/3.10/lib/python3.10/site-packages/minium/miniprogram/base_driver/page.py", line 383, in search_element
    return self._get_element_by_xpath(xpath)
  File "/Library/Frameworks/Python.framework/Versions/3.10/lib/python3.10/site-packages/minium/miniprogram/base_driver/page.py", line 537, in _get_element_by_xpath
    ret = self._send("Page.getElementByXpath", {"selector": xpath})
  File "/Library/Frameworks/Python.framework/Versions/3.10/lib/python3.10/site-packages/minium/miniprogram/base_driver/page.py", line 405, in _send
    return self.connection.send(method, params) if sync else self.connection.send_async(method, params)
  File "/Library/Frameworks/Python.framework/Versions/3.10/lib/python3.10/site-packages/minium/miniprogram/base_driver/connection.py", line 185, in send
    return self._receive_response(cmd)
  File "/Library/Frameworks/Python.framework/Versions/3.10/lib/python3.10/site-packages/minium/miniprogram/base_driver/connection.py", line 215, in _receive_response
    raise MiniTimeoutError(
minium.framework.exception.MiniTimeoutError: [call Page.getElementByXpath] receive from remote timeout, id: 3b8317d2-343b-41fd-a8b5-42f34fb222f4
ERROR 2022-09-27 16:40:11,070 connection.py _receive_response 206 [8b5111f2-f96d-4eb4-87ed-008a25be6899]: Remote debug connection lost
ERROR 2022-09-27 16:40:11,783 wx_minium.py connect_dev_tool 549 Remote debug connection lost
Traceback (most recent call last):
  File "/Library/Frameworks/Python.framework/Versions/3.10/lib/python3.10/site-packages/minium/miniprogram/wx_minium.py", line 539, in connect_dev_tool
    self._get_system_info()
  File "/Library/Frameworks/Python.framework/Versions/3.10/lib/python3.10/site-packages/minium/miniprogram/wx_minium.py", line 387, in _get_system_info
    system_info = self.get_system_info()
  File "/Library/Frameworks/Python.framework/Versions/3.10/lib/python3.10/site-packages/minium/miniprogram/base_driver/minium_log.py", line 135, in wrapper
    result = func(*args, **kwargs)
  File "/Library/Frameworks/Python.framework/Versions/3.10/lib/python3.10/site-packages/minium/miniprogram/wx_minium.py", line 588, in get_system_info
    self.call_wx_method("getSystemInfoSync")
  File "/Library/Frameworks/Python.framework/Versions/3.10/lib/python3.10/site-packages/minium/miniprogram/base_driver/minium_log.py", line 135, in wrapper
    result = func(*args, **kwargs)
  File "/Library/Frameworks/Python.framework/Versions/3.10/lib/python3.10/site-packages/minium/miniprogram/base_driver/minium_object.py", line 76, in call_wx_method
    return self._call_wx_method(method=method, args=args, plugin_appid=plugin_appid)
  File "/Library/Frameworks/Python.framework/Versions/3.10/lib/python3.10/site-packages/minium/miniprogram/base_driver/minium_object.py", line 287, in _call_wx_method
    return self.connection.send("App.callWxMethod", params)
  File "/Library/Frameworks/Python.framework/Versions/3.10/lib/python3.10/site-packages/minium/miniprogram/base_driver/connection.py", line 185, in send
    return self._receive_response(cmd)
  File "/Library/Frameworks/Python.framework/Versions/3.10/lib/python3.10/site-packages/minium/miniprogram/base_driver/connection.py", line 207, in _receive_response
    raise MiniAppError(err_msg)
minium.framework.exception.MiniAppError: Remote debug connection lost
ERROR 2022-09-27 16:40:11,987 connection.py _receive_response 206 [fe53c48b-b19e-45fa-a0a7-3f804391f16c]: Remote debug connection lost
ERROR 2022-09-27 16:40:12,726 wx_minium.py connect_dev_tool 549 Remote debug connection lost
Traceback (most recent call last):
  File "/Library/Frameworks/Python.framework/Versions/3.10/lib/python3.10/site-packages/minium/miniprogram/wx_minium.py", line 539, in connect_dev_tool
    self._get_system_info()
  File "/Library/Frameworks/Python.framework/Versions/3.10/lib/python3.10/site-packages/minium/miniprogram/wx_minium.py", line 387, in _get_system_info
    system_info = self.get_system_info()
  File "/Library/Frameworks/Python.framework/Versions/3.10/lib/python3.10/site-packages/minium/miniprogram/base_driver/minium_log.py", line 135, in wrapper
    result = func(*args, **kwargs)
  File "/Library/Frameworks/Python.framework/Versions/3.10/lib/python3.10/site-packages/minium/miniprogram/wx_minium.py", line 588, in get_system_info
    self.call_wx_method("getSystemInfoSync")
  File "/Library/Frameworks/Python.framework/Versions/3.10/lib/python3.10/site-packages/minium/miniprogram/base_driver/minium_log.py", line 135, in wrapper
    result = func(*args, **kwargs)
  File "/Library/Frameworks/Python.framework/Versions/3.10/lib/python3.10/site-packages/minium/miniprogram/base_driver/minium_object.py", line 76, in call_wx_method
    return self._call_wx_method(method=method, args=args, plugin_appid=plugin_appid)
  File "/Library/Frameworks/Python.framework/Versions/3.10/lib/python3.10/site-packages/minium/miniprogram/base_driver/minium_object.py", line 287, in _call_wx_method
    return self.connection.send("App.callWxMethod", params)
  File "/Library/Frameworks/Python.framework/Versions/3.10/lib/python3.10/site-packages/minium/miniprogram/base_driver/connection.py", line 185, in send
    return self._receive_response(cmd)
  File "/Library/Frameworks/Python.framework/Versions/3.10/lib/python3.10/site-packages/minium/miniprogram/base_driver/connection.py", line 207, in _receive_response
    raise MiniAppError(err_msg)
minium.framework.exception.MiniAppError: Remote debug connection lost
ERROR 2022-09-27 16:40:12,828 connection.py _receive_response 206 [7e98932b-a035-4b00-9ef5-6c4d613407ab]: Remote debug connection lost
ERROR 2022-09-27 16:40:13,682 wx_minium.py connect_dev_tool 549 Remote debug connection lost
Traceback (most recent call last):
  File "/Library/Frameworks/Python.framework/Versions/3.10/lib/python3.10/site-packages/minium/miniprogram/wx_minium.py", line 539, in connect_dev_tool
    self._get_system_info()
  File "/Library/Frameworks/Python.framework/Versions/3.10/lib/python3.10/site-packages/minium/miniprogram/wx_minium.py", line 387, in _get_system_info
    system_info = self.get_system_info()
  File "/Library/Frameworks/Python.framework/Versions/3.10/lib/python3.10/site-packages/minium/miniprogram/base_driver/minium_log.py", line 135, in wrapper
    result = func(*args, **kwargs)
  File "/Library/Frameworks/Python.framework/Versions/3.10/lib/python3.10/site-packages/minium/miniprogram/wx_minium.py", line 588, in get_system_info
    self.call_wx_method("getSystemInfoSync")
  File "/Library/Frameworks/Python.framework/Versions/3.10/lib/python3.10/site-packages/minium/miniprogram/base_driver/minium_log.py", line 135, in wrapper
    result = func(*args, **kwargs)
  File "/Library/Frameworks/Python.framework/Versions/3.10/lib/python3.10/site-packages/minium/miniprogram/base_driver/minium_object.py", line 76, in call_wx_method
    return self._call_wx_method(method=method, args=args, plugin_appid=plugin_appid)
  File "/Library/Frameworks/Python.framework/Versions/3.10/lib/python3.10/site-packages/minium/miniprogram/base_driver/minium_object.py", line 287, in _call_wx_method
    return self.connection.send("App.callWxMethod", params)
  File "/Library/Frameworks/Python.framework/Versions/3.10/lib/python3.10/site-packages/minium/miniprogram/base_driver/connection.py", line 185, in send
    return self._receive_response(cmd)
  File "/Library/Frameworks/Python.framework/Versions/3.10/lib/python3.10/site-packages/minium/miniprogram/base_driver/connection.py", line 207, in _receive_response
    raise MiniAppError(err_msg)
minium.framework.exception.MiniAppError: Remote debug connection lost
ERROR 2022-09-27 16:40:14,582 wx_minium.py launch_dev_tool 497 three times try to connect Dev tool has all fail ..., restart now...
ERROR 2022-09-27 16:40:14,608 connection.py _on_error       266 Connection to remote host was lost.
ERROR 2022-09-27 16:40:14,609 connection.py _on_error       266 Connection to remote host was lost.
ERROR 2022-09-27 16:40:14,609 connection.py _on_error       266 Connection to remote host was lost.
ERROR 2022-09-27 16:42:38,195 assertbase.py _teardown_collect 273 <bound method FirstTest.test_02_add_device_index of <minitest.FirstTest testMethod=test_02_add_device_index>>
Traceback (most recent call last):
  File "/Library/Frameworks/Python.framework/Versions/3.10/lib/python3.10/site-packages/minium/framework/libs/unittest/case.py", line 32, in testPartExecutor
    yield
  File "/Library/Frameworks/Python.framework/Versions/3.10/lib/python3.10/site-packages/minium/framework/libs/unittest/case.py", line 118, in run
    self._callTestMethod(testMethod)
  File "/Library/Frameworks/Python.framework/Versions/3.10/lib/python3.10/unittest/case.py", line 549, in _callTestMethod
    method()
  File "/Users/isentech/Desktop/python/miniu_test/minitest.py", line 25, in test_02_add_device_index
    self.page.get_element("/page/view/view[3]/view[1]/view[1]/view/view/view/view/view/view/view[1]/input").input(de.device_mac)
  File "/Library/Frameworks/Python.framework/Versions/3.10/lib/python3.10/site-packages/minium/miniprogram/base_driver/minium_log.py", line 135, in wrapper
    result = func(*args, **kwargs)
  File "/Library/Frameworks/Python.framework/Versions/3.10/lib/python3.10/site-packages/minium/miniprogram/base_driver/page.py", line 200, in get_element
    return self.get_element_by_xpath(
  File "/Library/Frameworks/Python.framework/Versions/3.10/lib/python3.10/site-packages/minium/miniprogram/base_driver/minium_log.py", line 135, in wrapper
    result = func(*args, **kwargs)
  File "/Library/Frameworks/Python.framework/Versions/3.10/lib/python3.10/site-packages/minium/miniprogram/base_driver/page.py", line 385, in get_element_by_xpath
    el = search_element()
  File "/Library/Frameworks/Python.framework/Versions/3.10/lib/python3.10/site-packages/minium/utils/utils.py", line 35, in wrapper
    r = func(*args, **kwargs)
  File "/Library/Frameworks/Python.framework/Versions/3.10/lib/python3.10/site-packages/minium/miniprogram/base_driver/page.py", line 383, in search_element
    return self._get_element_by_xpath(xpath)
  File "/Library/Frameworks/Python.framework/Versions/3.10/lib/python3.10/site-packages/minium/miniprogram/base_driver/page.py", line 537, in _get_element_by_xpath
    ret = self._send("Page.getElementByXpath", {"selector": xpath})
  File "/Library/Frameworks/Python.framework/Versions/3.10/lib/python3.10/site-packages/minium/miniprogram/base_driver/page.py", line 405, in _send
    return self.connection.send(method, params) if sync else self.connection.send_async(method, params)
  File "/Library/Frameworks/Python.framework/Versions/3.10/lib/python3.10/site-packages/minium/miniprogram/base_driver/connection.py", line 185, in send
    return self._receive_response(cmd)
  File "/Library/Frameworks/Python.framework/Versions/3.10/lib/python3.10/site-packages/minium/miniprogram/base_driver/connection.py", line 215, in _receive_response
    raise MiniTimeoutError(
minium.framework.exception.MiniTimeoutError: [call Page.getElementByXpath] receive from remote timeout, id: 17b5d50e-e712-4527-9d43-626cdc70af01
ERROR 2022-09-27 17:19:49,134 assertbase.py _teardown_collect 273 <bound method FirstTest.test_02_add_device_index of <minitest.FirstTest testMethod=test_02_add_device_index>>
Traceback (most recent call last):
  File "/Library/Frameworks/Python.framework/Versions/3.10/lib/python3.10/site-packages/minium/framework/libs/unittest/case.py", line 32, in testPartExecutor
    yield
  File "/Library/Frameworks/Python.framework/Versions/3.10/lib/python3.10/site-packages/minium/framework/libs/unittest/case.py", line 118, in run
    self._callTestMethod(testMethod)
  File "/Library/Frameworks/Python.framework/Versions/3.10/lib/python3.10/unittest/case.py", line 549, in _callTestMethod
    method()
  File "/Users/isentech/Desktop/python/miniu_test/minitest.py", line 26, in test_02_add_device_index
    self.page.get_element("/page/view/view[3]/view[1]/view[1]/view/view/view/view/view/view/view[1]/input").input(de.device_mac)
  File "/Library/Frameworks/Python.framework/Versions/3.10/lib/python3.10/site-packages/minium/miniprogram/base_driver/minium_log.py", line 135, in wrapper
    result = func(*args, **kwargs)
  File "/Library/Frameworks/Python.framework/Versions/3.10/lib/python3.10/site-packages/minium/miniprogram/base_driver/page.py", line 200, in get_element
    return self.get_element_by_xpath(
  File "/Library/Frameworks/Python.framework/Versions/3.10/lib/python3.10/site-packages/minium/miniprogram/base_driver/minium_log.py", line 135, in wrapper
    result = func(*args, **kwargs)
  File "/Library/Frameworks/Python.framework/Versions/3.10/lib/python3.10/site-packages/minium/miniprogram/base_driver/page.py", line 385, in get_element_by_xpath
    el = search_element()
  File "/Library/Frameworks/Python.framework/Versions/3.10/lib/python3.10/site-packages/minium/utils/utils.py", line 35, in wrapper
    r = func(*args, **kwargs)
  File "/Library/Frameworks/Python.framework/Versions/3.10/lib/python3.10/site-packages/minium/miniprogram/base_driver/page.py", line 383, in search_element
    return self._get_element_by_xpath(xpath)
  File "/Library/Frameworks/Python.framework/Versions/3.10/lib/python3.10/site-packages/minium/miniprogram/base_driver/page.py", line 537, in _get_element_by_xpath
    ret = self._send("Page.getElementByXpath", {"selector": xpath})
  File "/Library/Frameworks/Python.framework/Versions/3.10/lib/python3.10/site-packages/minium/miniprogram/base_driver/page.py", line 405, in _send
    return self.connection.send(method, params) if sync else self.connection.send_async(method, params)
  File "/Library/Frameworks/Python.framework/Versions/3.10/lib/python3.10/site-packages/minium/miniprogram/base_driver/connection.py", line 185, in send
    return self._receive_response(cmd)
  File "/Library/Frameworks/Python.framework/Versions/3.10/lib/python3.10/site-packages/minium/miniprogram/base_driver/connection.py", line 215, in _receive_response
    raise MiniTimeoutError(
minium.framework.exception.MiniTimeoutError: [call Page.getElementByXpath] receive from remote timeout, id: 8eb4bd5c-c1e2-4d30-85e6-db080214454f
ERROR 2022-09-27 17:21:13,318 connection.py _receive_response 206 [a7b3cf71-6d00-4ad9-8518-f679028730d1]: Remote debug connection lost
ERROR 2022-09-27 17:21:13,887 wx_minium.py connect_dev_tool 549 Remote debug connection lost
Traceback (most recent call last):
  File "/Library/Frameworks/Python.framework/Versions/3.10/lib/python3.10/site-packages/minium/miniprogram/wx_minium.py", line 539, in connect_dev_tool
    self._get_system_info()
  File "/Library/Frameworks/Python.framework/Versions/3.10/lib/python3.10/site-packages/minium/miniprogram/wx_minium.py", line 387, in _get_system_info
    system_info = self.get_system_info()
  File "/Library/Frameworks/Python.framework/Versions/3.10/lib/python3.10/site-packages/minium/miniprogram/base_driver/minium_log.py", line 135, in wrapper
    result = func(*args, **kwargs)
  File "/Library/Frameworks/Python.framework/Versions/3.10/lib/python3.10/site-packages/minium/miniprogram/wx_minium.py", line 588, in get_system_info
    self.call_wx_method("getSystemInfoSync")
  File "/Library/Frameworks/Python.framework/Versions/3.10/lib/python3.10/site-packages/minium/miniprogram/base_driver/minium_log.py", line 135, in wrapper
    result = func(*args, **kwargs)
  File "/Library/Frameworks/Python.framework/Versions/3.10/lib/python3.10/site-packages/minium/miniprogram/base_driver/minium_object.py", line 76, in call_wx_method
    return self._call_wx_method(method=method, args=args, plugin_appid=plugin_appid)
  File "/Library/Frameworks/Python.framework/Versions/3.10/lib/python3.10/site-packages/minium/miniprogram/base_driver/minium_object.py", line 287, in _call_wx_method
    return self.connection.send("App.callWxMethod", params)
  File "/Library/Frameworks/Python.framework/Versions/3.10/lib/python3.10/site-packages/minium/miniprogram/base_driver/connection.py", line 185, in send
    return self._receive_response(cmd)
  File "/Library/Frameworks/Python.framework/Versions/3.10/lib/python3.10/site-packages/minium/miniprogram/base_driver/connection.py", line 207, in _receive_response
    raise MiniAppError(err_msg)
minium.framework.exception.MiniAppError: Remote debug connection lost
ERROR 2022-09-27 17:21:14,065 connection.py _receive_response 206 [4af4d880-cd96-40f8-82a8-624ee8445244]: Remote debug connection lost
ERROR 2022-09-27 17:21:14,622 wx_minium.py connect_dev_tool 549 Remote debug connection lost
Traceback (most recent call last):
  File "/Library/Frameworks/Python.framework/Versions/3.10/lib/python3.10/site-packages/minium/miniprogram/wx_minium.py", line 539, in connect_dev_tool
    self._get_system_info()
  File "/Library/Frameworks/Python.framework/Versions/3.10/lib/python3.10/site-packages/minium/miniprogram/wx_minium.py", line 387, in _get_system_info
    system_info = self.get_system_info()
  File "/Library/Frameworks/Python.framework/Versions/3.10/lib/python3.10/site-packages/minium/miniprogram/base_driver/minium_log.py", line 135, in wrapper
    result = func(*args, **kwargs)
  File "/Library/Frameworks/Python.framework/Versions/3.10/lib/python3.10/site-packages/minium/miniprogram/wx_minium.py", line 588, in get_system_info
    self.call_wx_method("getSystemInfoSync")
  File "/Library/Frameworks/Python.framework/Versions/3.10/lib/python3.10/site-packages/minium/miniprogram/base_driver/minium_log.py", line 135, in wrapper
    result = func(*args, **kwargs)
  File "/Library/Frameworks/Python.framework/Versions/3.10/lib/python3.10/site-packages/minium/miniprogram/base_driver/minium_object.py", line 76, in call_wx_method
    return self._call_wx_method(method=method, args=args, plugin_appid=plugin_appid)
  File "/Library/Frameworks/Python.framework/Versions/3.10/lib/python3.10/site-packages/minium/miniprogram/base_driver/minium_object.py", line 287, in _call_wx_method
    return self.connection.send("App.callWxMethod", params)
  File "/Library/Frameworks/Python.framework/Versions/3.10/lib/python3.10/site-packages/minium/miniprogram/base_driver/connection.py", line 185, in send
    return self._receive_response(cmd)
  File "/Library/Frameworks/Python.framework/Versions/3.10/lib/python3.10/site-packages/minium/miniprogram/base_driver/connection.py", line 207, in _receive_response
    raise MiniAppError(err_msg)
minium.framework.exception.MiniAppError: Remote debug connection lost
ERROR 2022-09-27 17:21:14,762 connection.py _receive_response 206 [6a35fa0d-49b9-40e2-9e34-3b5519cd505f]: Remote debug connection lost
ERROR 2022-09-27 17:21:15,309 wx_minium.py connect_dev_tool 549 Remote debug connection lost
Traceback (most recent call last):
  File "/Library/Frameworks/Python.framework/Versions/3.10/lib/python3.10/site-packages/minium/miniprogram/wx_minium.py", line 539, in connect_dev_tool
    self._get_system_info()
  File "/Library/Frameworks/Python.framework/Versions/3.10/lib/python3.10/site-packages/minium/miniprogram/wx_minium.py", line 387, in _get_system_info
    system_info = self.get_system_info()
  File "/Library/Frameworks/Python.framework/Versions/3.10/lib/python3.10/site-packages/minium/miniprogram/base_driver/minium_log.py", line 135, in wrapper
    result = func(*args, **kwargs)
  File "/Library/Frameworks/Python.framework/Versions/3.10/lib/python3.10/site-packages/minium/miniprogram/wx_minium.py", line 588, in get_system_info
    self.call_wx_method("getSystemInfoSync")
  File "/Library/Frameworks/Python.framework/Versions/3.10/lib/python3.10/site-packages/minium/miniprogram/base_driver/minium_log.py", line 135, in wrapper
    result = func(*args, **kwargs)
  File "/Library/Frameworks/Python.framework/Versions/3.10/lib/python3.10/site-packages/minium/miniprogram/base_driver/minium_object.py", line 76, in call_wx_method
    return self._call_wx_method(method=method, args=args, plugin_appid=plugin_appid)
  File "/Library/Frameworks/Python.framework/Versions/3.10/lib/python3.10/site-packages/minium/miniprogram/base_driver/minium_object.py", line 287, in _call_wx_method
    return self.connection.send("App.callWxMethod", params)
  File "/Library/Frameworks/Python.framework/Versions/3.10/lib/python3.10/site-packages/minium/miniprogram/base_driver/connection.py", line 185, in send
    return self._receive_response(cmd)
  File "/Library/Frameworks/Python.framework/Versions/3.10/lib/python3.10/site-packages/minium/miniprogram/base_driver/connection.py", line 207, in _receive_response
    raise MiniAppError(err_msg)
minium.framework.exception.MiniAppError: Remote debug connection lost
ERROR 2022-09-27 17:21:15,868 wx_minium.py launch_dev_tool 497 three times try to connect Dev tool has all fail ..., restart now...
ERROR 2022-09-27 17:21:15,894 connection.py _on_error       266 Connection to remote host was lost.
ERROR 2022-09-27 17:21:15,895 connection.py _on_error       266 Connection to remote host was lost.
ERROR 2022-09-27 17:21:15,895 connection.py _on_error       266 Connection to remote host was lost.
ERROR 2022-09-27 17:23:35,467 assertbase.py _teardown_collect 273 <bound method FirstTest.test_02_add_device_index of <minitest.FirstTest testMethod=test_02_add_device_index>>
Traceback (most recent call last):
  File "/Library/Frameworks/Python.framework/Versions/3.10/lib/python3.10/site-packages/minium/framework/libs/unittest/case.py", line 32, in testPartExecutor
    yield
  File "/Library/Frameworks/Python.framework/Versions/3.10/lib/python3.10/site-packages/minium/framework/libs/unittest/case.py", line 118, in run
    self._callTestMethod(testMethod)
  File "/Library/Frameworks/Python.framework/Versions/3.10/lib/python3.10/unittest/case.py", line 549, in _callTestMethod
    method()
  File "/Users/isentech/Desktop/python/miniu_test/minitest.py", line 26, in test_02_add_device_index
    self.page.get_element("/page/view/view[3]/view[1]/view[1]/view/view/view/view/view/view/view[1]/input").input(de.device_mac)
  File "/Library/Frameworks/Python.framework/Versions/3.10/lib/python3.10/site-packages/minium/miniprogram/base_driver/minium_log.py", line 135, in wrapper
    result = func(*args, **kwargs)
  File "/Library/Frameworks/Python.framework/Versions/3.10/lib/python3.10/site-packages/minium/miniprogram/base_driver/page.py", line 200, in get_element
    return self.get_element_by_xpath(
  File "/Library/Frameworks/Python.framework/Versions/3.10/lib/python3.10/site-packages/minium/miniprogram/base_driver/minium_log.py", line 135, in wrapper
    result = func(*args, **kwargs)
  File "/Library/Frameworks/Python.framework/Versions/3.10/lib/python3.10/site-packages/minium/miniprogram/base_driver/page.py", line 385, in get_element_by_xpath
    el = search_element()
  File "/Library/Frameworks/Python.framework/Versions/3.10/lib/python3.10/site-packages/minium/utils/utils.py", line 35, in wrapper
    r = func(*args, **kwargs)
  File "/Library/Frameworks/Python.framework/Versions/3.10/lib/python3.10/site-packages/minium/miniprogram/base_driver/page.py", line 383, in search_element
    return self._get_element_by_xpath(xpath)
  File "/Library/Frameworks/Python.framework/Versions/3.10/lib/python3.10/site-packages/minium/miniprogram/base_driver/page.py", line 537, in _get_element_by_xpath
    ret = self._send("Page.getElementByXpath", {"selector": xpath})
  File "/Library/Frameworks/Python.framework/Versions/3.10/lib/python3.10/site-packages/minium/miniprogram/base_driver/page.py", line 405, in _send
    return self.connection.send(method, params) if sync else self.connection.send_async(method, params)
  File "/Library/Frameworks/Python.framework/Versions/3.10/lib/python3.10/site-packages/minium/miniprogram/base_driver/connection.py", line 185, in send
    return self._receive_response(cmd)
  File "/Library/Frameworks/Python.framework/Versions/3.10/lib/python3.10/site-packages/minium/miniprogram/base_driver/connection.py", line 215, in _receive_response
    raise MiniTimeoutError(
minium.framework.exception.MiniTimeoutError: [call Page.getElementByXpath] receive from remote timeout, id: 208bed38-75d5-4990-85f1-3d503e8a2e67
ERROR 2022-09-27 17:39:47,353 connection.py _receive_response 206 [a54ed0d3-ad16-4122-8e44-80c3c9815a81]: Remote debug connection lost
ERROR 2022-09-27 17:39:47,991 wx_minium.py connect_dev_tool 549 Remote debug connection lost
Traceback (most recent call last):
  File "/Library/Frameworks/Python.framework/Versions/3.10/lib/python3.10/site-packages/minium/miniprogram/wx_minium.py", line 539, in connect_dev_tool
    self._get_system_info()
  File "/Library/Frameworks/Python.framework/Versions/3.10/lib/python3.10/site-packages/minium/miniprogram/wx_minium.py", line 387, in _get_system_info
    system_info = self.get_system_info()
  File "/Library/Frameworks/Python.framework/Versions/3.10/lib/python3.10/site-packages/minium/miniprogram/base_driver/minium_log.py", line 135, in wrapper
    result = func(*args, **kwargs)
  File "/Library/Frameworks/Python.framework/Versions/3.10/lib/python3.10/site-packages/minium/miniprogram/wx_minium.py", line 588, in get_system_info
    self.call_wx_method("getSystemInfoSync")
  File "/Library/Frameworks/Python.framework/Versions/3.10/lib/python3.10/site-packages/minium/miniprogram/base_driver/minium_log.py", line 135, in wrapper
    result = func(*args, **kwargs)
  File "/Library/Frameworks/Python.framework/Versions/3.10/lib/python3.10/site-packages/minium/miniprogram/base_driver/minium_object.py", line 76, in call_wx_method
    return self._call_wx_method(method=method, args=args, plugin_appid=plugin_appid)
  File "/Library/Frameworks/Python.framework/Versions/3.10/lib/python3.10/site-packages/minium/miniprogram/base_driver/minium_object.py", line 287, in _call_wx_method
    return self.connection.send("App.callWxMethod", params)
  File "/Library/Frameworks/Python.framework/Versions/3.10/lib/python3.10/site-packages/minium/miniprogram/base_driver/connection.py", line 185, in send
    return self._receive_response(cmd)
  File "/Library/Frameworks/Python.framework/Versions/3.10/lib/python3.10/site-packages/minium/miniprogram/base_driver/connection.py", line 207, in _receive_response
    raise MiniAppError(err_msg)
minium.framework.exception.MiniAppError: Remote debug connection lost
ERROR 2022-09-27 17:39:48,176 connection.py _receive_response 206 [6da81610-172e-4879-bf9e-9139817400ca]: Remote debug connection lost
ERROR 2022-09-27 17:39:48,806 wx_minium.py connect_dev_tool 549 Remote debug connection lost
Traceback (most recent call last):
  File "/Library/Frameworks/Python.framework/Versions/3.10/lib/python3.10/site-packages/minium/miniprogram/wx_minium.py", line 539, in connect_dev_tool
    self._get_system_info()
  File "/Library/Frameworks/Python.framework/Versions/3.10/lib/python3.10/site-packages/minium/miniprogram/wx_minium.py", line 387, in _get_system_info
    system_info = self.get_system_info()
  File "/Library/Frameworks/Python.framework/Versions/3.10/lib/python3.10/site-packages/minium/miniprogram/base_driver/minium_log.py", line 135, in wrapper
    result = func(*args, **kwargs)
  File "/Library/Frameworks/Python.framework/Versions/3.10/lib/python3.10/site-packages/minium/miniprogram/wx_minium.py", line 588, in get_system_info
    self.call_wx_method("getSystemInfoSync")
  File "/Library/Frameworks/Python.framework/Versions/3.10/lib/python3.10/site-packages/minium/miniprogram/base_driver/minium_log.py", line 135, in wrapper
    result = func(*args, **kwargs)
  File "/Library/Frameworks/Python.framework/Versions/3.10/lib/python3.10/site-packages/minium/miniprogram/base_driver/minium_object.py", line 76, in call_wx_method
    return self._call_wx_method(method=method, args=args, plugin_appid=plugin_appid)
  File "/Library/Frameworks/Python.framework/Versions/3.10/lib/python3.10/site-packages/minium/miniprogram/base_driver/minium_object.py", line 287, in _call_wx_method
    return self.connection.send("App.callWxMethod", params)
  File "/Library/Frameworks/Python.framework/Versions/3.10/lib/python3.10/site-packages/minium/miniprogram/base_driver/connection.py", line 185, in send
    return self._receive_response(cmd)
  File "/Library/Frameworks/Python.framework/Versions/3.10/lib/python3.10/site-packages/minium/miniprogram/base_driver/connection.py", line 207, in _receive_response
    raise MiniAppError(err_msg)
minium.framework.exception.MiniAppError: Remote debug connection lost
ERROR 2022-09-27 17:39:48,995 connection.py _receive_response 206 [d3a9a0d8-3940-408a-8a22-c1392bceaa7a]: Remote debug connection lost
ERROR 2022-09-27 17:39:49,635 wx_minium.py connect_dev_tool 549 Remote debug connection lost
Traceback (most recent call last):
  File "/Library/Frameworks/Python.framework/Versions/3.10/lib/python3.10/site-packages/minium/miniprogram/wx_minium.py", line 539, in connect_dev_tool
    self._get_system_info()
  File "/Library/Frameworks/Python.framework/Versions/3.10/lib/python3.10/site-packages/minium/miniprogram/wx_minium.py", line 387, in _get_system_info
    system_info = self.get_system_info()
  File "/Library/Frameworks/Python.framework/Versions/3.10/lib/python3.10/site-packages/minium/miniprogram/base_driver/minium_log.py", line 135, in wrapper
    result = func(*args, **kwargs)
  File "/Library/Frameworks/Python.framework/Versions/3.10/lib/python3.10/site-packages/minium/miniprogram/wx_minium.py", line 588, in get_system_info
    self.call_wx_method("getSystemInfoSync")
  File "/Library/Frameworks/Python.framework/Versions/3.10/lib/python3.10/site-packages/minium/miniprogram/base_driver/minium_log.py", line 135, in wrapper
    result = func(*args, **kwargs)
  File "/Library/Frameworks/Python.framework/Versions/3.10/lib/python3.10/site-packages/minium/miniprogram/base_driver/minium_object.py", line 76, in call_wx_method
    return self._call_wx_method(method=method, args=args, plugin_appid=plugin_appid)
  File "/Library/Frameworks/Python.framework/Versions/3.10/lib/python3.10/site-packages/minium/miniprogram/base_driver/minium_object.py", line 287, in _call_wx_method
    return self.connection.send("App.callWxMethod", params)
  File "/Library/Frameworks/Python.framework/Versions/3.10/lib/python3.10/site-packages/minium/miniprogram/base_driver/connection.py", line 185, in send
    return self._receive_response(cmd)
  File "/Library/Frameworks/Python.framework/Versions/3.10/lib/python3.10/site-packages/minium/miniprogram/base_driver/connection.py", line 207, in _receive_response
    raise MiniAppError(err_msg)
minium.framework.exception.MiniAppError: Remote debug connection lost
ERROR 2022-09-27 17:39:50,239 wx_minium.py launch_dev_tool 497 three times try to connect Dev tool has all fail ..., restart now...
ERROR 2022-09-27 17:39:50,265 connection.py _on_error       266 Connection to remote host was lost.
ERROR 2022-09-27 17:39:50,266 connection.py _on_error       266 Connection to remote host was lost.
ERROR 2022-09-27 17:39:50,266 connection.py _on_error       266 Connection to remote host was lost.
ERROR 2022-09-27 18:00:23,226 assertbase.py _teardown_collect 273 <bound method FirstTest.test_01_bing_device of <minitest.FirstTest testMethod=test_01_bing_device>>
Traceback (most recent call last):
  File "/Library/Frameworks/Python.framework/Versions/3.10/lib/python3.10/site-packages/minium/framework/libs/unittest/case.py", line 32, in testPartExecutor
    yield
  File "/Library/Frameworks/Python.framework/Versions/3.10/lib/python3.10/site-packages/minium/framework/libs/unittest/case.py", line 118, in run
    self._callTestMethod(testMethod)
  File "/Library/Frameworks/Python.framework/Versions/3.10/lib/python3.10/unittest/case.py", line 549, in _callTestMethod
    method()
  File "/Users/isentech/Desktop/python/miniu_test/minitest.py", line 22, in test_01_bing_device
    self.assertEqual(page,"/pagesDevice/addDevice/addDevice")
  File "/Library/Frameworks/Python.framework/Versions/3.10/lib/python3.10/site-packages/minium/framework/assertbase.py", line 354, in _hook_assert
    return attr(*args, **kwargs)
  File "/Applications/PyCharm CE.app/Contents/plugins/python-ce/helpers/pycharm/teamcity/diff_tools.py", line 33, in _patched_equals
    old(self, first, second, msg)
  File "/Library/Frameworks/Python.framework/Versions/3.10/lib/python3.10/unittest/case.py", line 845, in assertEqual
    assertion_func(first, second, msg=msg)
  File "/Library/Frameworks/Python.framework/Versions/3.10/lib/python3.10/site-packages/minium/framework/assertbase.py", line 354, in _hook_assert
    return attr(*args, **kwargs)
  File "/Library/Frameworks/Python.framework/Versions/3.10/lib/python3.10/unittest/case.py", line 1226, in assertMultiLineEqual
    self.fail(self._formatMessage(msg, standardMsg))
  File "/Library/Frameworks/Python.framework/Versions/3.10/lib/python3.10/unittest/case.py", line 675, in fail
    raise self.failureException(msg)
AssertionError: '/pages/index/index' != '/pagesDevice/addDevice/addDevice'
- /pages/index/index
+ /pagesDevice/addDevice/addDevice

ERROR 2022-09-27 18:00:24,563 connection.py _receive_response 206 [f6c1fda8-b39b-4928-95e7-0dbb038b1b99]: no such element
ERROR 2022-09-27 18:00:26,236 assertbase.py _teardown_collect 273 <bound method FirstTest.test_02_add_device_index of <minitest.FirstTest testMethod=test_02_add_device_index>>
Traceback (most recent call last):
  File "/Library/Frameworks/Python.framework/Versions/3.10/lib/python3.10/site-packages/minium/framework/libs/unittest/case.py", line 32, in testPartExecutor
    yield
  File "/Library/Frameworks/Python.framework/Versions/3.10/lib/python3.10/site-packages/minium/framework/libs/unittest/case.py", line 118, in run
    self._callTestMethod(testMethod)
  File "/Library/Frameworks/Python.framework/Versions/3.10/lib/python3.10/unittest/case.py", line 549, in _callTestMethod
    method()
  File "/Users/isentech/Desktop/python/miniu_test/minitest.py", line 26, in test_02_add_device_index
    self.page.get_element("/page/view/view[3]/view[1]/view[1]/view/view/view/view/view/view/view[1]/input").input(de.device_mac)
  File "/Library/Frameworks/Python.framework/Versions/3.10/lib/python3.10/site-packages/minium/miniprogram/base_driver/minium_log.py", line 135, in wrapper
    result = func(*args, **kwargs)
  File "/Library/Frameworks/Python.framework/Versions/3.10/lib/python3.10/site-packages/minium/miniprogram/base_driver/page.py", line 200, in get_element
    return self.get_element_by_xpath(
  File "/Library/Frameworks/Python.framework/Versions/3.10/lib/python3.10/site-packages/minium/miniprogram/base_driver/minium_log.py", line 135, in wrapper
    result = func(*args, **kwargs)
  File "/Library/Frameworks/Python.framework/Versions/3.10/lib/python3.10/site-packages/minium/miniprogram/base_driver/page.py", line 387, in get_element_by_xpath
    raise MiniElementNotFoundError("element[%s] not found" % xpath)
minium.framework.exception.MiniElementNotFoundError: element[/page/view/view[3]/view[1]/view[1]/view/view/view/view/view/view/view[1]/input] not found
ERROR 2022-09-27 18:01:28,950 assertbase.py _teardown_collect 273 <bound method FirstTest.test_01_bing_device of <minitest.FirstTest testMethod=test_01_bing_device>>
Traceback (most recent call last):
  File "/Library/Frameworks/Python.framework/Versions/3.10/lib/python3.10/site-packages/minium/framework/libs/unittest/case.py", line 32, in testPartExecutor
    yield
  File "/Library/Frameworks/Python.framework/Versions/3.10/lib/python3.10/site-packages/minium/framework/libs/unittest/case.py", line 118, in run
    self._callTestMethod(testMethod)
  File "/Library/Frameworks/Python.framework/Versions/3.10/lib/python3.10/unittest/case.py", line 549, in _callTestMethod
    method()
  File "/Users/isentech/Desktop/python/miniu_test/minitest.py", line 22, in test_01_bing_device
    self.assertEqual(page,"/pagesDevice/addDevice/addDevice")
  File "/Library/Frameworks/Python.framework/Versions/3.10/lib/python3.10/site-packages/minium/framework/assertbase.py", line 354, in _hook_assert
    return attr(*args, **kwargs)
  File "/Applications/PyCharm CE.app/Contents/plugins/python-ce/helpers/pycharm/teamcity/diff_tools.py", line 33, in _patched_equals
    old(self, first, second, msg)
  File "/Library/Frameworks/Python.framework/Versions/3.10/lib/python3.10/unittest/case.py", line 845, in assertEqual
    assertion_func(first, second, msg=msg)
  File "/Library/Frameworks/Python.framework/Versions/3.10/lib/python3.10/site-packages/minium/framework/assertbase.py", line 354, in _hook_assert
    return attr(*args, **kwargs)
  File "/Library/Frameworks/Python.framework/Versions/3.10/lib/python3.10/unittest/case.py", line 1226, in assertMultiLineEqual
    self.fail(self._formatMessage(msg, standardMsg))
  File "/Library/Frameworks/Python.framework/Versions/3.10/lib/python3.10/unittest/case.py", line 675, in fail
    raise self.failureException(msg)
AssertionError: '/pages/index/index' != '/pagesDevice/addDevice/addDevice'
- /pages/index/index
+ /pagesDevice/addDevice/addDevice

ERROR 2022-09-27 18:08:55,684 assertbase.py _teardown_collect 273 <bound method FirstTest.test_01_bing_device of <minitest.FirstTest testMethod=test_01_bing_device>>
Traceback (most recent call last):
  File "/Library/Frameworks/Python.framework/Versions/3.10/lib/python3.10/site-packages/minium/framework/libs/unittest/case.py", line 32, in testPartExecutor
    yield
  File "/Library/Frameworks/Python.framework/Versions/3.10/lib/python3.10/site-packages/minium/framework/libs/unittest/case.py", line 118, in run
    self._callTestMethod(testMethod)
  File "/Library/Frameworks/Python.framework/Versions/3.10/lib/python3.10/unittest/case.py", line 549, in _callTestMethod
    method()
  File "/Users/isentech/Desktop/python/miniu_test/minitest.py", line 22, in test_01_bing_device
    self.assertEqual(page,"/pagesDevice/addDevice/addDevice")
  File "/Library/Frameworks/Python.framework/Versions/3.10/lib/python3.10/site-packages/minium/framework/assertbase.py", line 354, in _hook_assert
    return attr(*args, **kwargs)
  File "/Applications/PyCharm CE.app/Contents/plugins/python-ce/helpers/pycharm/teamcity/diff_tools.py", line 33, in _patched_equals
    old(self, first, second, msg)
  File "/Library/Frameworks/Python.framework/Versions/3.10/lib/python3.10/unittest/case.py", line 845, in assertEqual
    assertion_func(first, second, msg=msg)
  File "/Library/Frameworks/Python.framework/Versions/3.10/lib/python3.10/site-packages/minium/framework/assertbase.py", line 354, in _hook_assert
    return attr(*args, **kwargs)
  File "/Library/Frameworks/Python.framework/Versions/3.10/lib/python3.10/unittest/case.py", line 1226, in assertMultiLineEqual
    self.fail(self._formatMessage(msg, standardMsg))
  File "/Library/Frameworks/Python.framework/Versions/3.10/lib/python3.10/unittest/case.py", line 675, in fail
    raise self.failureException(msg)
AssertionError: '/pages/index/index' != '/pagesDevice/addDevice/addDevice'
- /pages/index/index
+ /pagesDevice/addDevice/addDevice

ERROR 2022-09-27 18:08:57,067 connection.py _receive_response 206 [52b4876a-941f-440f-85a5-10baeff7bce7]: no such element
ERROR 2022-09-27 18:08:58,633 assertbase.py _teardown_collect 273 <bound method FirstTest.test_02_add_device_index of <minitest.FirstTest testMethod=test_02_add_device_index>>
Traceback (most recent call last):
  File "/Library/Frameworks/Python.framework/Versions/3.10/lib/python3.10/site-packages/minium/framework/libs/unittest/case.py", line 32, in testPartExecutor
    yield
  File "/Library/Frameworks/Python.framework/Versions/3.10/lib/python3.10/site-packages/minium/framework/libs/unittest/case.py", line 118, in run
    self._callTestMethod(testMethod)
  File "/Library/Frameworks/Python.framework/Versions/3.10/lib/python3.10/unittest/case.py", line 549, in _callTestMethod
    method()
  File "/Users/isentech/Desktop/python/miniu_test/minitest.py", line 26, in test_02_add_device_index
    self.page.get_element("/page/view/view[3]/view[1]/view[1]/view/view/view/view/view/view/view[1]/input").input(de.device_mac)
  File "/Library/Frameworks/Python.framework/Versions/3.10/lib/python3.10/site-packages/minium/miniprogram/base_driver/minium_log.py", line 135, in wrapper
    result = func(*args, **kwargs)
  File "/Library/Frameworks/Python.framework/Versions/3.10/lib/python3.10/site-packages/minium/miniprogram/base_driver/page.py", line 200, in get_element
    return self.get_element_by_xpath(
  File "/Library/Frameworks/Python.framework/Versions/3.10/lib/python3.10/site-packages/minium/miniprogram/base_driver/minium_log.py", line 135, in wrapper
    result = func(*args, **kwargs)
  File "/Library/Frameworks/Python.framework/Versions/3.10/lib/python3.10/site-packages/minium/miniprogram/base_driver/page.py", line 387, in get_element_by_xpath
    raise MiniElementNotFoundError("element[%s] not found" % xpath)
minium.framework.exception.MiniElementNotFoundError: element[/page/view/view[3]/view[1]/view[1]/view/view/view/view/view/view/view[1]/input] not found
ERROR 2022-09-27 18:10:01,222 assertbase.py _teardown_collect 273 <bound method FirstTest.test_01_bing_device of <minitest.FirstTest testMethod=test_01_bing_device>>
Traceback (most recent call last):
  File "/Library/Frameworks/Python.framework/Versions/3.10/lib/python3.10/site-packages/minium/framework/libs/unittest/case.py", line 32, in testPartExecutor
    yield
  File "/Library/Frameworks/Python.framework/Versions/3.10/lib/python3.10/site-packages/minium/framework/libs/unittest/case.py", line 118, in run
    self._callTestMethod(testMethod)
  File "/Library/Frameworks/Python.framework/Versions/3.10/lib/python3.10/unittest/case.py", line 549, in _callTestMethod
    method()
  File "/Users/isentech/Desktop/python/miniu_test/minitest.py", line 23, in test_01_bing_device
    self.assertEqual(page,"/pagesDevice/addDevice/addDevice")
  File "/Library/Frameworks/Python.framework/Versions/3.10/lib/python3.10/site-packages/minium/framework/assertbase.py", line 354, in _hook_assert
    return attr(*args, **kwargs)
  File "/Applications/PyCharm CE.app/Contents/plugins/python-ce/helpers/pycharm/teamcity/diff_tools.py", line 33, in _patched_equals
    old(self, first, second, msg)
  File "/Library/Frameworks/Python.framework/Versions/3.10/lib/python3.10/unittest/case.py", line 845, in assertEqual
    assertion_func(first, second, msg=msg)
  File "/Library/Frameworks/Python.framework/Versions/3.10/lib/python3.10/site-packages/minium/framework/assertbase.py", line 354, in _hook_assert
    return attr(*args, **kwargs)
  File "/Library/Frameworks/Python.framework/Versions/3.10/lib/python3.10/unittest/case.py", line 1226, in assertMultiLineEqual
    self.fail(self._formatMessage(msg, standardMsg))
  File "/Library/Frameworks/Python.framework/Versions/3.10/lib/python3.10/unittest/case.py", line 675, in fail
    raise self.failureException(msg)
AssertionError: '/pages/index/index' != '/pagesDevice/addDevice/addDevice'
- /pages/index/index
+ /pagesDevice/addDevice/addDevice

ERROR 2022-09-27 18:51:28,873 assertbase.py _teardown_collect 273 <bound method FirstTest.test_01_bing_device of <minitest.FirstTest testMethod=test_01_bing_device>>
Traceback (most recent call last):
  File "/Library/Frameworks/Python.framework/Versions/3.10/lib/python3.10/site-packages/minium/framework/libs/unittest/case.py", line 32, in testPartExecutor
    yield
  File "/Library/Frameworks/Python.framework/Versions/3.10/lib/python3.10/site-packages/minium/framework/libs/unittest/case.py", line 118, in run
    self._callTestMethod(testMethod)
  File "/Library/Frameworks/Python.framework/Versions/3.10/lib/python3.10/unittest/case.py", line 549, in _callTestMethod
    method()
  File "/Users/isentech/Desktop/python/miniu_test/minitest.py", line 24, in test_01_bing_device
    self.assertEqual(page,"/pagesDevice/addDevice/addDevice")
  File "/Library/Frameworks/Python.framework/Versions/3.10/lib/python3.10/site-packages/minium/framework/assertbase.py", line 354, in _hook_assert
    return attr(*args, **kwargs)
  File "/Applications/PyCharm CE.app/Contents/plugins/python-ce/helpers/pycharm/teamcity/diff_tools.py", line 33, in _patched_equals
    old(self, first, second, msg)
  File "/Library/Frameworks/Python.framework/Versions/3.10/lib/python3.10/unittest/case.py", line 845, in assertEqual
    assertion_func(first, second, msg=msg)
  File "/Library/Frameworks/Python.framework/Versions/3.10/lib/python3.10/site-packages/minium/framework/assertbase.py", line 354, in _hook_assert
    return attr(*args, **kwargs)
  File "/Library/Frameworks/Python.framework/Versions/3.10/lib/python3.10/unittest/case.py", line 1226, in assertMultiLineEqual
    self.fail(self._formatMessage(msg, standardMsg))
  File "/Library/Frameworks/Python.framework/Versions/3.10/lib/python3.10/unittest/case.py", line 675, in fail
    raise self.failureException(msg)
AssertionError: '/pages/index/index' != '/pagesDevice/addDevice/addDevice'
- /pages/index/index
+ /pagesDevice/addDevice/addDevice

ERROR 2022-09-27 18:51:30,898 connection.py _receive_response 206 [7b2133c1-9c81-4811-bb48-99a8910bf839]: no such element
ERROR 2022-09-27 18:51:32,575 assertbase.py _teardown_collect 273 <bound method FirstTest.test_02_add_device_index of <minitest.FirstTest testMethod=test_02_add_device_index>>
Traceback (most recent call last):
  File "/Library/Frameworks/Python.framework/Versions/3.10/lib/python3.10/site-packages/minium/framework/libs/unittest/case.py", line 32, in testPartExecutor
    yield
  File "/Library/Frameworks/Python.framework/Versions/3.10/lib/python3.10/site-packages/minium/framework/libs/unittest/case.py", line 118, in run
    self._callTestMethod(testMethod)
  File "/Library/Frameworks/Python.framework/Versions/3.10/lib/python3.10/unittest/case.py", line 549, in _callTestMethod
    method()
  File "/Users/isentech/Desktop/python/miniu_test/minitest.py", line 30, in test_02_add_device_index
    self.page.get_element("/page/view/view[3]/view[1]/view[1]/view/view/view/view/view/view/view[1]/input").input(de.device_mac)
  File "/Library/Frameworks/Python.framework/Versions/3.10/lib/python3.10/site-packages/minium/miniprogram/base_driver/minium_log.py", line 135, in wrapper
    result = func(*args, **kwargs)
  File "/Library/Frameworks/Python.framework/Versions/3.10/lib/python3.10/site-packages/minium/miniprogram/base_driver/page.py", line 200, in get_element
    return self.get_element_by_xpath(
  File "/Library/Frameworks/Python.framework/Versions/3.10/lib/python3.10/site-packages/minium/miniprogram/base_driver/minium_log.py", line 135, in wrapper
    result = func(*args, **kwargs)
  File "/Library/Frameworks/Python.framework/Versions/3.10/lib/python3.10/site-packages/minium/miniprogram/base_driver/page.py", line 387, in get_element_by_xpath
    raise MiniElementNotFoundError("element[%s] not found" % xpath)
minium.framework.exception.MiniElementNotFoundError: element[/page/view/view[3]/view[1]/view[1]/view/view/view/view/view/view/view[1]/input] not found
ERROR 2022-09-27 18:51:41,867 assertbase.py _teardown_collect 273 <bound method FirstTest.test_01_bing_device of <minitest.FirstTest testMethod=test_01_bing_device>>
Traceback (most recent call last):
  File "/Library/Frameworks/Python.framework/Versions/3.10/lib/python3.10/site-packages/minium/framework/libs/unittest/case.py", line 32, in testPartExecutor
    yield
  File "/Library/Frameworks/Python.framework/Versions/3.10/lib/python3.10/site-packages/minium/framework/libs/unittest/case.py", line 118, in run
    self._callTestMethod(testMethod)
  File "/Library/Frameworks/Python.framework/Versions/3.10/lib/python3.10/unittest/case.py", line 549, in _callTestMethod
    method()
  File "/Users/isentech/Desktop/python/miniu_test/minitest.py", line 24, in test_01_bing_device
    self.assertEqual(page,"/pagesDevice/addDevice/addDevice")
  File "/Library/Frameworks/Python.framework/Versions/3.10/lib/python3.10/site-packages/minium/framework/assertbase.py", line 354, in _hook_assert
    return attr(*args, **kwargs)
  File "/Applications/PyCharm CE.app/Contents/plugins/python-ce/helpers/pycharm/teamcity/diff_tools.py", line 33, in _patched_equals
    old(self, first, second, msg)
  File "/Library/Frameworks/Python.framework/Versions/3.10/lib/python3.10/unittest/case.py", line 845, in assertEqual
    assertion_func(first, second, msg=msg)
  File "/Library/Frameworks/Python.framework/Versions/3.10/lib/python3.10/site-packages/minium/framework/assertbase.py", line 354, in _hook_assert
    return attr(*args, **kwargs)
  File "/Library/Frameworks/Python.framework/Versions/3.10/lib/python3.10/unittest/case.py", line 1226, in assertMultiLineEqual
    self.fail(self._formatMessage(msg, standardMsg))
  File "/Library/Frameworks/Python.framework/Versions/3.10/lib/python3.10/unittest/case.py", line 675, in fail
    raise self.failureException(msg)
AssertionError: '/pages/index/index' != '/pagesDevice/addDevice/addDevice'
- /pages/index/index
+ /pagesDevice/addDevice/addDevice

ERROR 2022-09-27 18:51:45,305 connection.py _receive_response 206 [a5f6d761-16ee-4e4e-8893-72b0b1e9e9c4]: no such element
ERROR 2022-09-27 18:51:46,856 assertbase.py _teardown_collect 273 <bound method FirstTest.test_02_add_device_index of <minitest.FirstTest testMethod=test_02_add_device_index>>
Traceback (most recent call last):
  File "/Library/Frameworks/Python.framework/Versions/3.10/lib/python3.10/site-packages/minium/framework/libs/unittest/case.py", line 32, in testPartExecutor
    yield
  File "/Library/Frameworks/Python.framework/Versions/3.10/lib/python3.10/site-packages/minium/framework/libs/unittest/case.py", line 118, in run
    self._callTestMethod(testMethod)
  File "/Library/Frameworks/Python.framework/Versions/3.10/lib/python3.10/unittest/case.py", line 549, in _callTestMethod
    method()
  File "/Users/isentech/Desktop/python/miniu_test/minitest.py", line 30, in test_02_add_device_index
    self.page.get_element("/page/view/view[3]/view[1]/view[1]/view/view/view/view/view/view/view[1]/input").input(de.device_mac)
  File "/Library/Frameworks/Python.framework/Versions/3.10/lib/python3.10/site-packages/minium/miniprogram/base_driver/minium_log.py", line 135, in wrapper
    result = func(*args, **kwargs)
  File "/Library/Frameworks/Python.framework/Versions/3.10/lib/python3.10/site-packages/minium/miniprogram/base_driver/page.py", line 200, in get_element
    return self.get_element_by_xpath(
  File "/Library/Frameworks/Python.framework/Versions/3.10/lib/python3.10/site-packages/minium/miniprogram/base_driver/minium_log.py", line 135, in wrapper
    result = func(*args, **kwargs)
  File "/Library/Frameworks/Python.framework/Versions/3.10/lib/python3.10/site-packages/minium/miniprogram/base_driver/page.py", line 387, in get_element_by_xpath
    raise MiniElementNotFoundError("element[%s] not found" % xpath)
minium.framework.exception.MiniElementNotFoundError: element[/page/view/view[3]/view[1]/view[1]/view/view/view/view/view/view/view[1]/input] not found
ERROR 2022-09-27 18:51:58,677 assertbase.py _teardown_collect 273 <bound method FirstTest.test_01_bing_device of <minitest.FirstTest testMethod=test_01_bing_device>>
Traceback (most recent call last):
  File "/Library/Frameworks/Python.framework/Versions/3.10/lib/python3.10/site-packages/minium/framework/libs/unittest/case.py", line 32, in testPartExecutor
    yield
  File "/Library/Frameworks/Python.framework/Versions/3.10/lib/python3.10/site-packages/minium/framework/libs/unittest/case.py", line 118, in run
    self._callTestMethod(testMethod)
  File "/Library/Frameworks/Python.framework/Versions/3.10/lib/python3.10/unittest/case.py", line 549, in _callTestMethod
    method()
  File "/Users/isentech/Desktop/python/miniu_test/minitest.py", line 24, in test_01_bing_device
    self.assertEqual(page,"/pagesDevice/addDevice/addDevice")
  File "/Library/Frameworks/Python.framework/Versions/3.10/lib/python3.10/site-packages/minium/framework/assertbase.py", line 354, in _hook_assert
    return attr(*args, **kwargs)
  File "/Applications/PyCharm CE.app/Contents/plugins/python-ce/helpers/pycharm/teamcity/diff_tools.py", line 33, in _patched_equals
    old(self, first, second, msg)
  File "/Library/Frameworks/Python.framework/Versions/3.10/lib/python3.10/unittest/case.py", line 845, in assertEqual
    assertion_func(first, second, msg=msg)
  File "/Library/Frameworks/Python.framework/Versions/3.10/lib/python3.10/site-packages/minium/framework/assertbase.py", line 354, in _hook_assert
    return attr(*args, **kwargs)
  File "/Library/Frameworks/Python.framework/Versions/3.10/lib/python3.10/unittest/case.py", line 1226, in assertMultiLineEqual
    self.fail(self._formatMessage(msg, standardMsg))
  File "/Library/Frameworks/Python.framework/Versions/3.10/lib/python3.10/unittest/case.py", line 675, in fail
    raise self.failureException(msg)
AssertionError: '/pages/index/index' != '/pagesDevice/addDevice/addDevice'
- /pages/index/index
+ /pagesDevice/addDevice/addDevice

ERROR 2022-09-27 18:52:08,660 assertbase.py _teardown_collect 273 <bound method FirstTest.test_02_add_device_index of <minitest.FirstTest testMethod=test_02_add_device_index>>
Traceback (most recent call last):
  File "/Library/Frameworks/Python.framework/Versions/3.10/lib/python3.10/site-packages/minium/framework/libs/unittest/case.py", line 32, in testPartExecutor
    yield
  File "/Library/Frameworks/Python.framework/Versions/3.10/lib/python3.10/site-packages/minium/framework/libs/unittest/case.py", line 118, in run
    self._callTestMethod(testMethod)
  File "/Library/Frameworks/Python.framework/Versions/3.10/lib/python3.10/unittest/case.py", line 549, in _callTestMethod
    method()
  File "/Users/isentech/Desktop/python/miniu_test/minitest.py", line 36, in test_02_add_device_index
    self.assertEqual(devices_sum,1)
  File "/Library/Frameworks/Python.framework/Versions/3.10/lib/python3.10/site-packages/minium/framework/assertbase.py", line 354, in _hook_assert
    return attr(*args, **kwargs)
  File "/Applications/PyCharm CE.app/Contents/plugins/python-ce/helpers/pycharm/teamcity/diff_tools.py", line 33, in _patched_equals
    old(self, first, second, msg)
  File "/Library/Frameworks/Python.framework/Versions/3.10/lib/python3.10/unittest/case.py", line 845, in assertEqual
    assertion_func(first, second, msg=msg)
  File "/Library/Frameworks/Python.framework/Versions/3.10/lib/python3.10/unittest/case.py", line 838, in _baseAssertEqual
    raise self.failureException(msg)
AssertionError: 0 != 1
