ERROR 2022-09-21 17:46:46,184 assertbase.py _teardown_collect 273 <bound method FirstTest.test_01_bing_device of <minitest.FirstTest testMethod=test_01_bing_device>>
Traceback (most recent call last):
  File "/Library/Frameworks/Python.framework/Versions/3.10/lib/python3.10/site-packages/minium/framework/libs/unittest/case.py", line 32, in testPartExecutor
    yield
  File "/Library/Frameworks/Python.framework/Versions/3.10/lib/python3.10/site-packages/minium/framework/libs/unittest/case.py", line 118, in run
    self._callTestMethod(testMethod)
  File "/Library/Frameworks/Python.framework/Versions/3.10/lib/python3.10/unittest/case.py", line 549, in _callTestMethod
    method()
  File "/Users/isentech/Desktop/python/miniu_test/minitest.py", line 19, in test_01_bing_device
    self.assertCountEqual(page,'pagesDevice/addDevice/addDevice')
  File "/Library/Frameworks/Python.framework/Versions/3.10/lib/python3.10/site-packages/minium/framework/assertbase.py", line 354, in _hook_assert
    return attr(*args, **kwargs)
  File "/Library/Frameworks/Python.framework/Versions/3.10/lib/python3.10/unittest/case.py", line 1206, in assertCountEqual
    self.fail(msg)
  File "/Library/Frameworks/Python.framework/Versions/3.10/lib/python3.10/unittest/case.py", line 675, in fail
    raise self.failureException(msg)
AssertionError: Element counts were not equal:
First has 3, Second has 2:  '/'
First has 1, Second has 3:  'a'
First has 3, Second has 1:  'g'
First has 1, Second has 7:  'e'
First has 2, Second has 0:  'l'
First has 2, Second has 0:  'o'
First has 2, Second has 3:  'i'
First has 2, Second has 0:  'n'
First has 0, Second has 3:  'D'
First has 0, Second has 3:  'v'
First has 0, Second has 3:  'c'
First has 0, Second has 4:  'd'
ERROR 2022-09-21 18:57:12,273 assertbase.py _teardown_collect 273 <bound method FirstTest.test_01_bing_device of <minitest.FirstTest testMethod=test_01_bing_device>>
Traceback (most recent call last):
  File "/Library/Frameworks/Python.framework/Versions/3.10/lib/python3.10/site-packages/minium/framework/libs/unittest/case.py", line 32, in testPartExecutor
    yield
  File "/Library/Frameworks/Python.framework/Versions/3.10/lib/python3.10/site-packages/minium/framework/libs/unittest/case.py", line 118, in run
    self._callTestMethod(testMethod)
  File "/Library/Frameworks/Python.framework/Versions/3.10/lib/python3.10/unittest/case.py", line 549, in _callTestMethod
    method()
  File "/Users/isentech/Desktop/python/miniu_test/minitest.py", line 19, in test_01_bing_device
    self.assertCountEqual(page,'pagesDevice/addDevice/addDevice')
  File "/Library/Frameworks/Python.framework/Versions/3.10/lib/python3.10/site-packages/minium/framework/assertbase.py", line 354, in _hook_assert
    return attr(*args, **kwargs)
  File "/Library/Frameworks/Python.framework/Versions/3.10/lib/python3.10/unittest/case.py", line 1206, in assertCountEqual
    self.fail(msg)
  File "/Library/Frameworks/Python.framework/Versions/3.10/lib/python3.10/unittest/case.py", line 675, in fail
    raise self.failureException(msg)
AssertionError: Element counts were not equal:
First has 3, Second has 2:  '/'
ERROR 2022-09-21 18:59:21,506 assertbase.py _teardown_collect 273 <bound method FirstTest.test_01_bing_device of <minitest.FirstTest testMethod=test_01_bing_device>>
Traceback (most recent call last):
  File "/Library/Frameworks/Python.framework/Versions/3.10/lib/python3.10/site-packages/minium/framework/libs/unittest/case.py", line 32, in testPartExecutor
    yield
  File "/Library/Frameworks/Python.framework/Versions/3.10/lib/python3.10/site-packages/minium/framework/libs/unittest/case.py", line 118, in run
    self._callTestMethod(testMethod)
  File "/Library/Frameworks/Python.framework/Versions/3.10/lib/python3.10/unittest/case.py", line 549, in _callTestMethod
    method()
  File "/Users/isentech/Desktop/python/miniu_test/minitest.py", line 19, in test_01_bing_device
    self.assertCountEqual(page,'pagesDevice/addDevice/addDevice')
  File "/Library/Frameworks/Python.framework/Versions/3.10/lib/python3.10/site-packages/minium/framework/assertbase.py", line 354, in _hook_assert
    return attr(*args, **kwargs)
  File "/Library/Frameworks/Python.framework/Versions/3.10/lib/python3.10/unittest/case.py", line 1206, in assertCountEqual
    self.fail(msg)
  File "/Library/Frameworks/Python.framework/Versions/3.10/lib/python3.10/unittest/case.py", line 675, in fail
    raise self.failureException(msg)
AssertionError: Element counts were not equal:
First has 3, Second has 2:  '/'
ERROR 2022-09-21 19:14:17,200 assertbase.py _teardown_collect 273 <bound method FirstTest.test_01_bing_device of <minitest.FirstTest testMethod=test_01_bing_device>>
Traceback (most recent call last):
  File "/Library/Frameworks/Python.framework/Versions/3.10/lib/python3.10/site-packages/minium/framework/libs/unittest/case.py", line 32, in testPartExecutor
    yield
  File "/Library/Frameworks/Python.framework/Versions/3.10/lib/python3.10/site-packages/minium/framework/libs/unittest/case.py", line 118, in run
    self._callTestMethod(testMethod)
  File "/Library/Frameworks/Python.framework/Versions/3.10/lib/python3.10/unittest/case.py", line 549, in _callTestMethod
    method()
  File "/Users/isentech/Desktop/python/miniu_test/minitest.py", line 21, in test_01_bing_device
    self.assertEqual(page,"pagesDevice/addDevice/addDevice")
  File "/Library/Frameworks/Python.framework/Versions/3.10/lib/python3.10/site-packages/minium/framework/assertbase.py", line 354, in _hook_assert
    return attr(*args, **kwargs)
  File "/Applications/PyCharm CE.app/Contents/plugins/python-ce/helpers/pycharm/teamcity/diff_tools.py", line 33, in _patched_equals
    old(self, first, second, msg)
  File "/Library/Frameworks/Python.framework/Versions/3.10/lib/python3.10/unittest/case.py", line 845, in assertEqual
    assertion_func(first, second, msg=msg)
  File "/Library/Frameworks/Python.framework/Versions/3.10/lib/python3.10/site-packages/minium/framework/assertbase.py", line 354, in _hook_assert
    return attr(*args, **kwargs)
  File "/Library/Frameworks/Python.framework/Versions/3.10/lib/python3.10/unittest/case.py", line 1226, in assertMultiLineEqual
    self.fail(self._formatMessage(msg, standardMsg))
  File "/Library/Frameworks/Python.framework/Versions/3.10/lib/python3.10/unittest/case.py", line 675, in fail
    raise self.failureException(msg)
AssertionError: '/pagesDevice/addDevice/addDevice' != 'pagesDevice/addDevice/addDevice'
- /pagesDevice/addDevice/addDevice
? -
+ pagesDevice/addDevice/addDevice

